Workbook

Sheet Dashboard
A1: Retail Sales Dashboard
A4: Total Sales | E4: Total Profit | I4: Total Orders | M4: Avg Order Value
A5: =SUM('Cleaned Data'!$N$2:$N$651) -> 883903.36 | E5: =SUM('Cleaned Data'!$O$2:$O$651) -> 102358.47 | I5: =COUNTA('Cleaned Data'!$A$2:$A$651) -> 650 | M5: =AVERAGE('Cleaned Data'!$N$2:$N$651) -> 1359.8513

Sheet Raw Data
A1: Order ID | B1: Order Date | C1: Ship Date | D1: Customer Name | E1: Segment | F1: Region | G1: City | H1: Category | I1: Sub-Category | J1: Ship Mode | K1: Quantity | L1: Unit Price | M1: Discount | N1: Sales | O1: Profit
A2: ORD-100109 | B2: 24/09/2024 | C2: 26/09/2024 | D2: Yuki Ali | E2: Corporate | F2: West | G2: Pune | H2: Home & Kitchen | I2: Blender | J2: Second Class | K2: 4 | L2: 425.62 | M2: 0.15 | N2: 1447.11 | O2: -67.96
A3: ORD-100329 | B3: 26/11/2023 | C3: 29/11/2023 | D3: Grace Brown | E3: Consumer | F3: EAST | G3: Patna | H3: Office Supplies | I3: Printer Paper | J3: Standard Class | L3: 331.25 | N3: 331.25 | O3: 37.91
A4: ORD-100057 | B4: 2023-04-16 | C4: 2023-04-23 | D4: Noah Chen | E4: Corporate | F4: east | G4: Patna | H4: Home & Kitchen | I4: Toaster | J4: First Class | K4: 2 | L4: 1149.48 | M4: 0.15 | N4: 1954.12 | O4: 189.53
A5: ORD-100134 | B5: 2023-01-01 | C5: 2023-01-04 | D5: Raj Garcia | E5: Home Office | F5: NORTH | G5: Delhi | H5: Electronics | I5: Smartphone | J5: Standard Class | K5: 2 | L5: 28.81 | M5: 0.15 | N5: 48.98 | O5: -4.42
A6: ORD-100115 | B6: 08/05/2023 | C6: 08/09/2023 | D6: Anaya Ali | F6: East | G6: Bhubaneswar | H6: Electronics | I6: Smartwatch | J6: Same Day | K6: 5 | L6: 265.31 | M6: 0.15 | N6: 1127.57 | O6: 340.94
A7: ORD-100549 | B7: 10/07/2024 | C7: 10/10/2024 | D7: Ivan Petrov | E7: Home Office | F7: WEST | G7: Pune | H7: clothing | I7: T-Shirt | J7: Second Class | K7: 2 | L7: 682.48 | M7: 0 | N7: 1364.96 | O7: 366.17
A8: ORD-100542 | B8: 2023-12-17 | C8: 2023-12-24 | D8: wei wang | E8: Corporate | F8: east | G8: Kolkata | H8: Clothing | I8: Cap | J8: Second Class | L8: 797.58 | N8: 797.58 | O8: 1.76
A9: ORD-100343 | B9: 20-08-2024 | C9: 26-08-2024 | E9: Corporate | F9: WEST | G9: Mumbai | H9: OFFICE SUPPLIES | I9: Binder | J9: Standard Class | K9: 5 | L9: 767.54 | N9: 3837.7 | O9: 396.96
A10: ORD-100277 | B10: 06-11-2024 | C10: 11-11-2024 | D10: amara khan | E10: Home Office | F10: WEST | G10: Ahmedabad | H10: Clothing | I10: T-Shirt | J10: Standard Class | K10: 2 | L10: 133.84 | N10: 267.68 | O10: -25.53
A11: ORD-100232 | B11: 09-05-2024 | C11: 14-05-2024 | D11: Noah Okafor | E11: Home Office | F11: Nort | G11: Delhi | H11: Furniture | I11: Office Chair | J11: Standard Class | L11: 609.66 | N11: 609.66 | O11: 150.14
A12: ORD-100563 | B12: 2023-11-24 | C12: 2023-11-25 | D12: Amara Patel | E12: Consumer | F12: South | G12: Bengaluru | H12: electronics | I12: Tablet | J12: First Class | K12: 2 | L12: 1071.37 | N12: 2142.74
A13: ORD-100490 | B13: 04/04/2023 | C13: 04/11/2023 | D13: carlos johnson | E13: Consumer | F13: West | G13: Mumbai | H13: Furniture | I13: Bookshelf | J13: Same Day | K13: 1 | L13: 941.12 | M13: 0.05 | N13: 894.06 | O13: -34.3
A14: ORD-100281 | B14: May 06, 2023 | C14: May 08, 2023 | D14: Hassan Okafor | E14: Home Office | F14: east | G14: Patna | H14: Furniture | I14: Desk | J14: Standard Class | K14: 2 | L14: 715.98 | M14: 0.15 | N14: 1217.17 | O14: 394.91
A15: ORD-100023 | B15: 2024-07-31 | C15: 2024-08-06 | F15: South | G15: Chennai | H15: CLOTHING | I15: Jeans | J15: Same Day | K15: 1 | L15: 1088.78 | M15: 0.2 | N15: 871.02 | O15: 252.67
A16: ORD-100419 | B16: Jun 19, 2024 | C16: Jun 26, 2024 | D16: Ivan Johnson | E16: Corporate | F16: West | G16: Ahmedabad | H16: Clothing | I16: Jacket | J16: Standard Class | K16: 4 | L16: 994.68 | M16: 0.15 | N16: 3381.91 | O16: 325.15
A17: ORD-100452 | B17: 04/19/2023 | C17: 04/23/2023 | D17: Amara Brown | E17: Corporate | F17: NORTH | G17: Delhi | H17: Electronics | I17: Headphones | J17: Standard Class | K17: 2 | L17: 281.89 | N17: 563.78 | O17: 171.9
A18: ORD-100110 | B18: 11/07/2023 | C18: 14/07/2023 | D18: Grace Sharma | F18: West | G18: Mumbai | H18: Home & Kitchen | I18: Cookware Set | J18: Second Class | K18: 2 | L18: 590.12 | M18: 0.05 | N18: 1121.23 | O18: -13.67
A19: ORD-100229 | B19: 2023-11-28 | C19: 2023-12-05 | E19: Home Office | F19: east | G19: Bhubaneswar | H19: Office Supplies | I19: Notebook | J19: Standard Class | K19: 3 | L19: 363.84 | M19: 0.2 | N19: 873.22 | O19: 68.31
A20: ORD-100352 | B20: 01-08-2023 | C20: 06-08-2023 | E20: Consumer | F20: North | G20: Delhi | H20: HOME & KITCHEN | I20: Vacuum Cleaner | J20: Standard Class | K20: 5 | L20: 543.87 | M20: 0.1 | N20: 2447.41 | O20: 458.86
A21: ORD-100568 | B21: 24/02/2024 | C21: 29/02/2024 | D21: Grace Johnson | E21: Consumer | F21: South | G21: Chennai | H21: home & kitchen | I21: Vacuum Cleaner | J21: Standard Class | K21: 1 | L21: 138.08 | M21: 0 | N21: 138.08
A22: ORD-100610 | B22: 05/21/2023 | C22: 05/24/2023 | D22: Tom Okafor | F22: East | G22: Bhubaneswar | H22: home & kitchen | I22: Air Fryer | J22: Standard Class | K22: 1 | L22: 367.5 | N22: 367.5 | O22: 42.42
A23: ORD-100235 | B23: 30-06-2024 | C23: 01-07-2024 | D23: Maria Tanaka | F23: EAST | G23: Kolkata | H23: OFFICE SUPPLIES | I23: Printer Paper | J23: First Class | K23: 2 | L23: 856.91 | N23: 1713.82 | O23: 179.97
A24: ORD-100202 | B24: 2023-04-07 | C24: 2023-04-12 | D24: Raj Okafor | E24: Home Office | F24: West | G24: Mumbai | H24: clothing | I24: Jeans | J24: Standard Class | K24: 1 | L24: 243.02 | N24: 243.02 | O24: 44.5
A25: ORD-100386 | B25: 2023-05-17 | C25: 2023-05-22 | D25: Priya Petrov | E25: Consumer | F25: SOUTH | G25: Bengaluru | H25: home & kitchen | I25: Cookware Set | J25: Standard Class | K25: 2 | L25: 94.77 | N25: 189.54 | O25: 59.01
A26: ORD-100551 | B26: 02-06-2024 | C26: 08-06-2024 | D26: Aisha Novak | E26: Consumer | F26: SOUTH | G26: Chennai | H26: Office Supplies | I26: Notebook | J26: Second Class | K26: 1 | L26: 231.8 | M26: 0.1 | N26: 208.62 | O26: -12.1
A27: ORD-100351 | B27: 07/07/2023 | C27: 13/07/2023 | D27: Diego Sharma | E27: Home Office | F27: South | G27: Hyderabad | H27: HOME & KITCHEN | I27: Toaster | J27: Standard Class | L27: 464.67 | N27: 464.67 | O27: 65.97
A28: ORD-100470 | B28: 22-02-2024 | C28: 28-02-2024 | D28: Carlos Lee | E28: Home Office | F28: West | G28: Mumbai | H28: Clothing | I28: Jeans | J28: Second Class | K28: 2 | L28: 1111.23 | M28: 0.05 | N28: 2111.34 | O28: -133.69
A29: ORD-100191 | B29: 09-10-2023 | C29: 13-10-2023 | D29: Maria Martin | E29: Corporate | F29: North | G29: Delhi | H29: Clothing | I29: Jacket | J29: First Class | K29: 4 | L29: 593.35 | M29: 0.2 | N29: 1898.72 | O29: 259.33
A30: ORD-100465 | B30: 10/11/2023 | C30: 10/16/2023 | D30: Wei Tanaka | E30: Home Office | F30: West | G30: Pune | H30: home & kitchen | I30: Cookware Set | J30: Same Day | K30: 5 | L30: 75.01 | M30: 0 | N30: 375.05 | O30: 109.17
A31: ORD-100600 | B31: Oct 27, 2023 | C31: Oct 29, 2023 | D31: Maria Okafor | F31: west | G31: Mumbai | H31: Furniture | I31: Dining Table | J31: First Class | K31: 5 | L31: 449.67 | M31: 0.1 | N31: 2023.51 | O31: 345.96
A32: ORD-100589 | B32: 17-10-2023 | C32: 19-10-2023 | D32: Olga Smith | E32: Home Office | F32: Nort | G32: Delhi | H32: office supplies | I32: Notebook | J32: Same Day | K32: 2 | L32: 630.59 | M32: 0.2 | N32: 1008.94 | O32: -87.81
A33: ORD-100586 | B33: 2024-09-18 | C33: 2024-09-19 | D33: Lucas Ali | E33: Corporate | F33: east | G33: Bhubaneswar | H33: Furniture | I33: Desk | J33: First Class | K33: 3 | L33: 822.45 | M33: 0.15 | N33: 2097.25 | O33: 323.81
A34: ORD-100357 | B34: Dec 11, 2024 | C34: Dec 13, 2024 | D34: Arjun Brown | E34: Consumer | F34: North | G34: Chandigarh | H34: home & kitchen | I34: Vacuum Cleaner | J34: Standard Class | K34: 5 | L34: 815.09 | N34: 4075.45 | O34: -375.18
A35: ORD-100294 | B35: 2024-04-27 | C35: 2024-05-03 | D35: Anaya Brown | E35: Consumer | F35: West | G35: Mumbai | H35: Electronics | I35: Laptop | J35: Second Class | K35: 1 | L35: 988.72 | M35: 0.15 | N35: 840.41 | O35: 180.11
A36: ORD-100442 | B36: Dec 19, 2024 | C36: Dec 22, 2024 | D36: Fatima Petrov | E36: Home Office | F36: west | G36: Pune | H36: OFFICE SUPPLIES | I36: Printer Paper | J36: Same Day | K36: 2 | L36: 54.11 | M36: 0.2 | N36: 1298.7 | O36: -4.36
A37: ORD-100360 | B37: 2023-11-15 | C37: 2023-11-17 | D37: Sofia Petrov | E37: Home Office | F37: south | G37: Hyderabad | H37: Furniture | I37: Dining Table | J37: Same Day | K37: 1 | L37: 514.36 | M37: 0.15 | N37: 437.21 | O37: 44.47
A38: ORD-100401 | B38: 30/03/2024 | C38: 06/04/2024 | D38: Noah Okafor | E38: Home Office | F38: East | G38: Patna | H38: Electronics | I38: Smartphone | J38: Second Class | K38: 2 | L38: 579.11 | M38: 0.2 | N38: 926.58 | O38: 134.01
A39: ORD-100417 | B39: 03/09/2024 | C39: 05/09/2024 | D39: Isabella Said | E39: Home Office | F39: South | G39: Chennai | H39: Clothing | I39: Jacket | J39: Second Class | K39: 5 | L39: 988.5 | M39: 0.2 | N39: 3954 | O39: -127.6
A40: ORD-100098 | B40: 2024-03-20 | C40: 2024-03-26 | D40: Omar Khan | E40: Corporate | F40: North | G40: Delhi | H40: electronics | I40: Bluetooth Speaker | J40: First Class | K40: 2 | L40: 103.81 | N40: 207.62 | O40: 63.44
...

Sheet Cleaning Log
A1: Data Cleaning Log
A3: Original raw rows: 670
A4: Removed fully blank rows: 5
A5: Removed exact duplicate rows: 15
A6: Rows remaining after removing blanks/duplicates: 650
A7: Corrected 29 misspelled Region values ('Nort' -> 'North')
A8: Standardized casing/whitespace in Customer Name, Region, Category, City, Segment, Ship Mode, Sub-Category
A9: Filled missing Customer Name (36 rows) with 'Unknown Customer'
A10: Filled missing Segment (163 rows) with 'Unknown'
A11: Parsed Order Date and Ship Date from 5 mixed formats into a single consistent date format
A12: Ship Date left blank for 21 rows with no recorded ship date (flagged for review, not guessed)
A13: Filled missing Quantity (65 rows) with the median quantity for that product Category
... A38: Order ORD-100029: Profit 1194.71 -> capped to 993.15

Sheet Cleaned Data
A1: Order ID | B1: Order Date | C1: Ship Date | D1: Customer Name | E1: Segment | F1: Region | G1: City | H1: Category | I1: Sub-Category | J1: Ship Mode | K1: Quantity | L1: Unit Price | M1: Discount | N1: Sales | O1: Profit | P1: Order Month | Q1: Profit Margin % | R1: Outlier Flag | T1: Outlier thresholds (IQR method)
A2: ORD-100134 | B2: 44927 | C2: 44930 | D2: Raj Garcia | E2: Home Office | F2: North | G2: Delhi | H2: Electronics | I2: Smartphone | J2: Standard Class | K2: 2 | L2: 28.81 | M2: 0.15 | N2: 48.98 | O2: -4.42 | P2: =TEXT(B2,"mmm-yyyy") -> Jan-2023 | Q2: =IFERROR(O2/N2,"") -> -0.090240915 | R2: =IF(OR(N2>$U$3,N2<$U$2),"Sales Outlier",IF(OR(O2>$U$6,O2<$U$4),"Profit Outlier","")) | T2: Sales lower bound | U2: =QUARTILE(N2:N651,1)-3*(QUARTILE(N2:N651,3)-QUARTILE(N2:N651,1)) -> -3842.32
A3: ORD-100228 | B3: 44928 | C3: 44929 | D3: Unknown Customer | E3: Consumer | F3: West | G3: Ahmedabad | H3: Clothing | I3: Jeans | J3: Second Class | K3: 2 | L3: 851.76 | M3: 0.05 | N3: 1618.34 | O3: 455.78 | P3: =TEXT(B3,"mmm-yyyy") -> Jan-2023 | Q3: =IFERROR(O3/N3,"") -> 0.28163427 | R3: =IF(OR(N3>$U$3,N3<$U$2),"Sales Outlier",IF(OR(O3>$U$6,O3<$U$4),"Profit Outlier","")) | T3: Sales upper bound | U3: =QUARTILE(N2:N651,3)+3*(QUARTILE(N2:N651,3)-QUARTILE(N2:N651,1)) -> 6212.69
A4: ORD-100495 | B4: 44930 | C4: 44933 | D4: Mei Khan | E4: Consumer | F4: South | G4: Hyderabad | H4: Home & Kitchen | I4: Toaster | J4: Standard Class | K4: 2 | L4: 764.18 | M4: 0 | N4: 1528.36 | O4: 486.97 | P4: =TEXT(B4,"mmm-yyyy") -> Jan-2023 | Q4: =IFERROR(O4/N4,"") -> 0.31862258 | R4: =IF(OR(N4>$U$3,N4<$U$2),"Sales Outlier",IF(OR(O4>$U$6,O4<$U$4),"Profit Outlier","")) | T4: Profit lower bound | U4: =QUARTILE(O2:O651,1)-3*(QUARTILE(O2:O651,3)-QUARTILE(O2:O651,1)) -> -733.2225
A5: ORD-100082 | B5: 44932 | C5: 44937 | D5: Emma Petrov | E5: Unknown | F5: West | G5: Pune | H5: Office Supplies | I5: Pen Set | J5: Second Class | K5: 1 | L5: 819.02 | M5: 0.05 | N5: 778.07 | O5: 149.97 | P5: =TEXT(B5,"mmm-yyyy") -> Jan-2023 | Q5: =IFERROR(O5/N5,"") -> 0.19274615 | R5: =IF(OR(N5>$U$3,N5<$U$2),"Sales Outlier",IF(OR(O5>$U$6,O5<$U$4),"Profit Outlier","")) | U5: =QUARTILE(O2:O651,1)-3*(QUARTILE(O2:O651,3)-QUARTILE(O2:O651,1)) -> -733.2225
A6: ORD-100101 | B6: 44932 | C6: 44935 | D6: Maria Kim | E6: Unknown | F6: West | G6: Pune | H6: Furniture | I6: Sofa | J6: Standard Class | K6: 4 | L6: 436.04 | M6: 0 | N6: 1744.16 | O6: 262.75 | P6: =TEXT(B6,"mmm-yyyy") -> Jan-2023 | Q6: =IFERROR(O6/N6,"") -> 0.15064558 | R6: =IF(OR(N6>$U$3,N6<$U$2),"Sales Outlier",IF(OR(O6>$U$6,O6<$U$4),"Profit Outlier","")) | T6: Profit upper bound | U6: =QUARTILE(O2:O651,3)+3*(QUARTILE(O2:O651,3)-QUARTILE(O2:O651,1)) -> 993.1525
A7: ORD-100210 | B7: 44933 | C7: 44936 | D7: Raj Brown | E7: Home Office | F7: East | G7: Patna | H7: Home & Kitchen | I7: Blender | J7: Second Class | K7: 2 | L7: 1192.13 | M7: 0.1 | N7: 2145.83 | O7: 279.11 | P7: =TEXT(B7,"mmm-yyyy") -> Jan-2023 | Q7: =IFERROR(O7/N7,"") -> 0.13007088 | R7: =IF(OR(N7>$U$3,N7<$U$2),"Sales Outlier",IF(OR(O7>$U$6,O7<$U$4),"Profit Outlier",""))
A8: ORD-100532 | B8: 44933 | C8: 44938 | D8: John Smith | E8: Home Office | F8: West | G8: Mumbai | H8: Home & Kitchen | I8: Toaster | J8: Second Class | K8: 1 | L8: 484.75 | M8: 0.1 | N8: 436.28 | O8: 71.1 | P8: =TEXT(B8,"mmm-yyyy") -> Jan-2023 | Q8: =IFERROR(O8/N8,"") -> 0.16296874 | R8: =IF(OR(N8>$U$3,N8<$U$2),"Sales Outlier",IF(OR(O8>$U$6,O8<$U$4),"Profit Outlier",""))
A9: ORD-100163 | B9: 44933 | C9: 45114 | D9: Hassan Garcia | E9: Home Office | F9: North | G9: Lucknow | H9: Home & Kitchen | I9: Toaster | J9: Second Class | K9: 2 | L9: 1109.62 | M9: 0 | N9: 1109.62 | O9: 329.14 | P9: =TEXT(B9,"mmm-yyyy") -> Jan-2023 | Q9: =IFERROR(O9/N9,"") -> 0.29662407 | R9: =IF(OR(N9>$U$3,N9<$U$2),"Sales Outlier",IF(OR(O9>$U$6,O9<$U$4),"Profit Outlier",""))
A10: ORD-100053 | B10: 44934 | C10: 44938 | D10: Emma Garcia | E10: Home Office | F10: East | G10: Kolkata | H10: Furniture | I10: Bookshelf | J10: Same Day | K10: 3 | L10: 350.89 | M10: 0 | N10: 1052.67 | O10: 82.83 | P10: =TEXT(B10,"mmm-yyyy") -> Jan-2023 | Q10: =IFERROR(O10/N10,"") -> 0.078685628 | R10: =IF(OR(N10>$U$3,N10<$U$2),"Sales Outlier",IF(OR(O10>$U$6,O10<$U$4),"Profit Outlier",""))
A11: ORD-100367 | B11: 44934 | C11: 44940 | D11: Priya Khan | E11: Unknown | F11: South | G11: Hyderabad | H11: Clothing | I11: Sneakers | J11: First Class | K11: 1 | L11: 16.36 | M11: 0.1 | N11: 14.72 | O11: 1.97 | P11: =TEXT(B11,"mmm-yyyy") -> Jan-2023 | Q11: =IFERROR(O11/N11,"") -> 0.13383152 | R11: =IF(OR(N11>$U$3,N11<$U$2),"Sales Outlier",IF(OR(O11>$U$6,O11<$U$4),"Profit Outlier",""))
A12: ORD-100385 | B12: 44937 | C12: 44941 | D12: Ivan Garcia | E12: Consumer | F12: North | G12: Chandigarh | H12: Electronics | I12: Bluetooth Speaker | J12: Same Day | K12: 3 | L12: 667.22 | M12: 0.15 | N12: 1701.41 | O12: 212.43 | P12: =TEXT(B12,"mmm-yyyy") -> Jan-2023 | Q12: =IFERROR(O12/N12,"") -> 0.12485527 | R12: =IF(OR(N12>$U$3,N12<$U$2),"Sales Outlier",IF(OR(O12>$U$6,O12<$U$4),"Profit Outlier",""))
A13: ORD-100009 | B13: 44942 | C13: 44943 | D13: Tom Rossi | E13: Corporate | F13: South | G13: Bengaluru | H13: Electronics | I13: Tablet | J13: Second Class | K13: 1 | L13: 65.45 | M13: 0.2 | N13: 52.36 | O13: -128.24 | P13: =TEXT(B13,"mmm-yyyy") -> Jan-2023 | Q13: =IFERROR(O13/N13,"") -> -2.4491979 | R13: =IF(OR(N13>$U$3,N13<$U$2),"Sales Outlier",IF(OR(O13>$U$6,O13<$U$4),"Profit Outlier",""))
A14: ORD-100543 | B14: 44944 | C14: 44946 | D14: Mei Martin | E14: Consumer | F14: West | G14: Ahmedabad | H14: Home & Kitchen | I14: Cookware Set | J14: Same Day | K14: 2 | L14: 1008.82 | M14: 0.05 | N14: 1916.76 | O14: 121.13 | P14: =TEXT(B14,"mmm-yyyy") -> Jan-2023 | Q14: =IFERROR(O14/N14,"") -> 0.063195184 | R14: =IF(OR(N14>$U$3,N14<$U$2),"Sales Outlier",IF(OR(O14>$U$6,O14<$U$4),"Profit Outlier",""))
A15: ORD-100458 | B15: 44945 | C15: 44950 | D15: Diego Fernandez | E15: Unknown | F15: North | G15: Lucknow | H15: Furniture | I15: Dining Table | J15: Second Class | K15: 5 | L15: 819.92 | M15: 0 | N15: 4099.6 | O15: -155.8 | P15: =TEXT(B15,"mmm-yyyy") -> Jan-2023 | Q15: =IFERROR(O15/N15,"") -> -0.038003708 | R15: =IF(OR(N15>$U$3,N15<$U$2),"Sales Outlier",IF(OR(O15>$U$6,O15<$U$4),"Profit Outlier",""))
A16: ORD-100324 | B16: 44946 | C16: 44947 | D16: Nina Johnson | E16: Corporate | F16: North | G16: Delhi | H16: Home & Kitchen | I16: Air Fryer | J16: Standard Class | K16: 2 | L16: 901.92 | M16: 0.2 | N16: 1443.07 | O16: 394.48 | P16: =TEXT(B16,"mmm-yyyy") -> Jan-2023 | Q16: =IFERROR(O16/N16,"") -> 0.27336165 | R16: =IF(OR(N16>$U$3,N16<$U$2),"Sales Outlier",IF(OR(O16>$U$6,O16<$U$4),"Profit Outlier",""))
A17: ORD-100570 | B17: 44948 | C17: 44952 | D17: Carlos Sharma | E17: Corporate | F17: East | G17: Bhubaneswar | H17: Furniture | I17: Sofa | J17: Same Day | K17: 3 | L17: 1058.92 | M17: 0.1 | N17: 2859.08 | O17: -125.05 | P17: =TEXT(B17,"mmm-yyyy") -> Jan-2023 | Q17: =IFERROR(O17/N17,"") -> -0.043737846 | R17: =IF(OR(N17>$U$3,N17<$U$2),"Sales Outlier",IF(OR(O17>$U$6,O17<$U$4),"Profit Outlier",""))
A18: ORD-100089 | B18: 44950 | C18: 44953 | D18: Hassan Novak | E18: Corporate | F18: West | G18: Mumbai | H18: Home & Kitchen | I18: Cookware Set | J18: Second Class | K18: 2 | L18: 1002.61 | M18: 0 | N18: 2005.22 | O18: 215.12 | P18: =TEXT(B18,"mmm-yyyy") -> Jan-2023 | Q18: =IFERROR(O18/N18,"") -> 0.10728 | R18: =IF(OR(N18>$U$3,N18<$U$2),"Sales Outlier",IF(OR(O18>$U$6,O18<$U$4),"Profit Outlier",""))
... A35: ORD-100304 | B35: 44964 | C35: 45023 | D35: Tom Fernandez | E35: Corporate | F35: North | G35: Chandigarh | H35: Electronics | I35: Smartwatch | J35: First Class | K35: 5 | L35: 115.6 | M35: 0.1 | N35: 520.2 | O35: 130.45 | P35: =TEXT(B35,"mmm-yyyy") -> Feb-2023 | Q35: =IFERROR(O35/N35,"") -> 0.25076894 | R35: =IF(OR(N35>$U$3,N35<$U$2),"Sales Outlier",IF(OR(O35>$U$6,O35<$U$4),"Profit Outlier",""))
A36: ORD-100598 | B36: 44965 | D36: Kenji Petrov | E36: Consumer | F36: South | G36: Hyderabad | H36: Furniture | I36: Office Chair | J36: Second Class | K36: 5 | L36: 815.23 | M36: 0 | N36: 4076.15 | O36: -292.04 | P36: =TEXT(B36,"mmm-yyyy") -> Feb-2023 | Q36: =IFERROR(O36/N36,"") -> -0.071646039 | R36: =IF(OR(N36>$U$3,N36<$U$2),"Sales Outlier",IF(OR(O36>$U$6,O36<$U$4),"Profit Outlier",""))
A37: ORD-100464 | B37: 44966 | C37: 44971 | D37: Liam Kim | E37: Consumer | F37: North | G37: Delhi | H37: Furniture | I37: Dining Table | J37: First Class | K37: 3 | L37: 408.35 | M37: 0.15 | N37: 1041.29 | O37: 39.68 | P37: =TEXT(B37,"mmm-yyyy") -> Feb-2023 | Q37: =IFERROR(O37/N37,"") -> 0.038106579 | R37: =IF(OR(N37>$U$3,N37<$U$2),"Sales Outlier",IF(OR(O37>$U$6,O37<$U$4),"Profit Outlier",""))
A38: ORD-100533 | B38: 44967 | C38: 44974 | D38: Mei Chen | E38: Corporate | F38: South | G38: Hyderabad | H38: Office Supplies | I38: Stapler | J38: Same Day | K38: 1 | L38: 36.34 | M38: 0.2 | N38: 29.07 | O38: -0.18 | P38: =TEXT(B38,"mmm-yyyy") -> Feb-2023 | Q38: =IFERROR(O38/N38,"") -> -0.0061919505 | R38: =IF(OR(N38>$U$3,N38<$U$2),"Sales Outlier",IF(OR(O38>$U$6,O38<$U$4),"Profit Outlier",""))
A39: ORD-100014 | B39: 44967 | C39: 44970 | D39: Sofia Khan | E39: Unknown | F39: South | G39: Hyderabad | H39: Clothing | I39: Jeans | J39: First Class | K39: 1 | L39: 373.37 | M39: 0 | N39: 373.37 | O39: 88.59 | P39: =TEXT(B39,"mmm-yyyy") -> Feb-2023 | Q39: =IFERROR(O39/N39,"") -> 0.23727134 | R39: =IF(OR(N39>$U$3,N39<$U$2),"Sales Outlier",IF(OR(O39>$U$6,O39<$U$4),"Profit Outlier",""))
A40: ORD-100222 | B40: 44967 | C40: 44972 | D40: Maria Sharma | E40: Home Office | F40: West | G40: Pune | H40: Clothing | I40: T-Shirt | J40: Standard Class | K40: 2 | L40: 624.85 | M40: 0.15 | N40: 1062.25 | O40: 114.3 | P40: =TEXT(B40,"mmm-yyyy") -> Feb-2023 | Q40: =IFERROR(O40/N40,"") -> 0.10760179 | R40: =IF(OR(N40>$U$3,N40<$U$2),"Sales Outlier",IF(OR(O40>$U$6,O40<$U$4),"Profit Outlier",""))
A41: ORD-100212 | B41: 44969 | C41: 44972 | D41: Carlos Brown | E41: Consumer | F41: South | G41: Hyderabad | H41: Home & Kitchen | I41: Blender | J41: Second Class | K41: 5 | L41: 69.68 | M41: 0.2 | N41: 278.72 | O41: 63.89 | P41: =TEXT(B41,"mmm-yyyy") -> Feb-2023 | Q41: =IFERROR(O41/N41,"") -> 0.22922646 | R41: =IF(OR(N41>$U$3,N41<$U$2),"Sales Outlier",IF(OR(O41>$U$6,O41<$U$4),"Profit Outlier",""))
A42: ORD-100253 | B42: 44970 | C42: 44974 | D42: Ethan Martin | E42: Corporate | F42: West | G42: Ahmedabad | H42: Electronics | I42: Headphones | J42: Second Class | K42: 4 | L42: 71.99 | M42: 0 | N42: 287.96 | O42: 46.28 | P42: =TEXT(B42,"mmm-yyyy") -> Feb-2023 | Q42: =IFERROR(O42/N42,"") -> 0.16071677 | R42: =IF(OR(N42>$U$3,N42<$U$2),"Sales Outlier",IF(OR(O42>$U$6,O42<$U$4),"Profit Outlier",""))
A43: ORD-100625 | B43: 44970 | C43: 44971 | D43: Carlos Smith | E43: Unknown | F43: West | G43: Ahmedabad | H43: Furniture | I43: Office Chair | J43: Same Day | K43: 2 | L43: 198.69 | M43: 0.2 | N43: 317.9 | O43: 76.11 | P43: =TEXT(B43,"mmm-yyyy") -> Feb-2023 | Q43: =IFERROR(O43/N43,"") -> 0.23941491 | R43: =IF(OR(N43>$U$3,N43<$U$2),"Sales Outlier",IF(OR(O43>$U$6,O43<$U$4),"Profit Outlier",""))
A44: ORD-100337 | B44: 44972 | C44: 44973 | D44: Omar Petrov | E44: Home Office | F44: West | G44: Pune | H44: Home & Kitchen | I44: Toaster | J44: Standard Class | K44: 2 | L44: 295.57 | M44: 0 | N44: 591.14 | O44: 96.15 | P44: =TEXT(B44,"mmm-yyyy") -> Feb-2023 | Q44: =IFERROR(O44/N44,"") -> 0.16265183 | R44: =IF(OR(N44>$U$3,N44<$U$2),"Sales Outlier",IF(OR(O44>$U$6,O44<$U$4),"Profit Outlier",""))
A45: ORD-100066 | B45: 44975 | C45: 44982 | D45: Liam Khan | E45: Unknown | F45: West | G45: Ahmedabad | H45: Office Supplies | I45: Notebook | J45: Same Day | K45: 2 | L45: 346.9 | M45: 0 | N45: 693.8 | O45: 67.91 | P45: =TEXT(B45,"mmm-yyyy") -> Feb-2023 | Q45: =IFERROR(O45/N45,"") -> 0.097881234 | R45: =IF(OR(N45>$U$3,N45<$U$2),"Sales Outlier",IF(OR(O45>$U$6,O45<$U$4),"Profit Outlier",""))
A46: ORD-100274 | B46: 44976 | C46: 44979 | D46: Arjun Chen | E46: Corporate | F46: North | G46: Delhi | H46: Office Supplies | I46: Printer Paper | J46: First Class | K46: 5 | L46: 765.32 | M46: 0.1 | N46: 3443.94 | O46: 583.55 | P46: =TEXT(B46,"mmm-yyyy") -> Feb-2023 | Q46: =IFERROR(O46/N46,"") -> 0.16944256 | R46: =IF(OR(N46>$U$3,N46<$U$2),"Sales Outlier",IF(OR(O46>$U$6,O46<$U$4),"Profit Outlier",""))
A47: ORD-100562 | B47: 44976 | C47: 44981 | D47: Unknown Customer | E47: Home Office | F47: East | G47: Bhubaneswar | H47: Home & Kitchen | I47: Air Fryer | J47: Standard Class | K47: 2 | L47: 770.91 | M47: 0 | N47: 1541.82 | O47: -23.58 | P47: =TEXT(B47,"mmm-yyyy") -> Feb-2023 | Q47: =IFERROR(O47/N47,"") -> -0.015293614 | R47: =IF(OR(N47>$U$3,N47<$U$2),"Sales Outlier",IF(OR(O47>$U$6,O47<$U$4),"Profit Outlier",""))
A48: ORD-100154 | B48: 44976 | C48: 44982 | D48: Kenji Fernandez | E48: Corporate | F48: North | G48: Delhi | H48: Home & Kitchen | I48: Blender | J48: Standard Class | K48: 1 | L48: 786.01 | M48: 0 | N48: 786.01 | O48: 167.29 | P48: =TEXT(B48,"mmm-yyyy") -> Feb-2023 | Q48: =IFERROR(O48/N48,"") -> 0.21283444 | R48: =IF(OR(N48>$U$3,N48<$U$2),"Sales Outlier",IF(OR(O48>$U$6,O48<$U$4),"Profit Outlier",""))
... A145: ORD-100643 | B145: 45108 | C145: 45113 | D145: John Petrov | E145: Unknown | F145: East | G145: Kolkata | H145: Electronics | I145: Smartphone | J145: Second Class | K145: 5 | L145: 675.1 | M145: 0.1 | N145: 3037.95 | O145: -167.83 | P145: =TEXT(B145,"mmm-yyyy") -> Jul-2023 | Q145: =IFERROR(O145/N145,"") -> -0.055244491 | R145: =IF(OR(N145>$U$3,N145<$U$2),"Sales Outlier",IF(OR(O145>$U$6,O145<$U$4),"Profit Outlier",""))
A146: ORD-100557 | B146: 45108 | D146: Liam Okafor | E146: Corporate | F146: West | G146: Mumbai | H146: Furniture | I146: Desk | J146: First Class | K146: 2 | L146: 119.56 | M146: 0.1 | N146: 215.21 | O146: 12.49 | P146: =TEXT(B146,"mmm-yyyy") -> Jul-2023 | Q146: =IFERROR(O146/N146,"") -> 0.058036337 | R146: =IF(OR(N146>$U$3,N146<$U$2),"Sales Outlier",IF(OR(O146>$U$6,O146<$U$4),"Profit Outlier",""))
A147: ORD-100151 | B147: 45111 | C147: 45118 | D147: Noah Johnson | E147: Unknown | F147: East | G147: Bhubaneswar | H147: Clothing | I147: Cap | J147: Same Day | K147: 2 | L147: 176.15 | M147: 0 | N147: 176.15 | O147: -1.02 | P147: =TEXT(B147,"mmm-yyyy") -> Jul-2023 | Q147: =IFERROR(O147/N147,"") -> -0.0057905194 | R147: =IF(OR(N147>$U$3,N147<$U$2),"Sales Outlier",IF(OR(O147>$U$6,O147<$U$4),"Profit Outlier",""))
A148: ORD-100478 | B148: 45111 | C148: 45114 | D148: Zara Ali | E148: Unknown | F148: West | G148: Ahmedabad | H148: Home & Kitchen | I148: Cookware Set | J148: Second Class | K148: 4 | L148: 583.66 | M148: 0 | N148: 2334.64 | O148: 141.73 | P148: =TEXT(B148,"mmm-yyyy") -> Jul-2023 | Q148: =IFERROR(O148/N148,"") -> 0.060707432 | R148: =IF(OR(N148>$U$3,N148<$U$2),"Sales Outlier",IF(OR(O148>$U$6,O148<$U$4),"Profit Outlier",""))
A149: ORD-100579 | B149: 45113 | C149: 45266 | D149: Maria Chen | E149: Consumer | F149: South | G149: Hyderabad | H149: Electronics | I149: Smartphone | J149: Standard Class | K149: 1 | L149: 216.64 | M149: 0 | N149: 216.64 | O149: 57.01 | P149: =TEXT(B149,"mmm-yyyy") -> Jul-2023 | Q149: =IFERROR(O149/N149,"") -> 0.26315547 | R149: =IF(OR(N149>$U$3,N149<$U$2),"Sales Outlier",IF(OR(O149>$U$6,O149<$U$4),"Profit Outlier",""))
A150: ORD-100190 | B150: 45114 | C150: 45120 | D150: Ivan Patel | E150: Corporate | F150: West | G150: Pune | H150: Office Supplies | I150: Printer Paper | J150: Standard Class | K150: 2 | L150: 1073.71 | M150: 0.1 | N150: 1932.68 | O150: -13.43 | P150: =TEXT(B150,"mmm-yyyy") -> Jul-2023 | Q150: =IFERROR(O150/N150,"") -> -0.0069489 | R150: =IF(OR(N150>$U$3,N150<$U$2),"Sales Outlier",IF(OR(O150>$U$6,O150<$U$4),"Profit Outlier",""))
A151: ORD-100351 | B151: 45114 | C151: 45120 | D151: Diego Sharma | E151: Home Office | F151: South | G151: Hyderabad | H151: Home & Kitchen | I151: Toaster | J151: Standard Class | K151: 2 | L151: 464.67 | M151: 0 | N151: 464.67 | O151: 65.97 | P151: =TEXT(B151,"mmm-yyyy") -> Jul-2023 | Q151: =IFERROR(O151/N151,"") -> 0.14197172 | R151: =IF(OR(N151>$U$3,N151<$U$2),"Sales Outlier",IF(OR(O151>$U$6,O151<$U$4),"Profit Outlier",""))
A152: ORD-100069 | B152: 45117 | C152: 45121 | D152: Ivan Novak | E152: Unknown | F152: West | G152: Mumbai | H152: Office Supplies | I152: Printer Paper | J152: First Class | K152: 2 | L152: 1152.82 | M152: 0 | N152: 2305.64 | O152: 803.2 | P152: =TEXT(B152,"mmm-yyyy") -> Jul-2023 | Q152: =IFERROR(O152/N152,"") -> 0.34836314 | R152: =IF(OR(N152>$U$3,N152<$U$2),"Sales Outlier",IF(OR(O152>$U$6,O152<$U$4),"Profit Outlier",""))
...

Sheet Summary
A1: Summary Tables (live formulas over Cleaned Data)
A3: Sales & Profit by Region
A4: Region | B4: Total Sales | C4: Total Profit | D4: Order Count | E4: Profit Margin %
A5: East | B5: =SUMIF('Cleaned Data'!$F:$F,A5,'Cleaned Data'!$N:$N) -> 191790.13 | C5: =SUMIF('Cleaned Data'!$F:$F,A5,'Cleaned Data'!$O:$O) -> 21881.09 | D5: =COUNTIF('Cleaned Data'!$F:$F,A5) -> 152 | E5: =IFERROR(C5/B5,"") -> 0.11408872
A6: North | B6: =SUMIF('Cleaned Data'!$F:$F,A6,'Cleaned Data'!$N:$N) -> 210985.61 | C6: =SUMIF('Cleaned Data'!$F:$F,A6,'Cleaned Data'!$O:$O) -> 20728.26 | D6: =COUNTIF('Cleaned Data'!$F:$F,A6) -> 141 | E6: =IFERROR(C6/B6,"") -> 0.098244899
A7: South | B7: =SUMIF('Cleaned Data'!$F:$F,A7,'Cleaned Data'!$N:$N) -> 208599.73 | C7: =SUMIF('Cleaned Data'!$F:$F,A7,'Cleaned Data'!$O:$O) -> 24978.92 | D7: =COUNTIF('Cleaned Data'!$F:$F,A7) -> 171 | E7: =IFERROR(C7/B7,"") -> 0.1197457
A8: West | B8: =SUMIF('Cleaned Data'!$F:$F,A8,'Cleaned Data'!$N:$N) -> 272527.89 | C8: =SUMIF('Cleaned Data'!$F:$F,A8,'Cleaned Data'!$O:$O) -> 34770.2 | D8: =COUNTIF('Cleaned Data'!$F:$F,A8) -> 186 | E8: =IFERROR(C8/B8,"") -> 0.12758401
A10: Sales & Profit by Category
A11: Category | B11: Total Sales | C11: Total Profit | D11: Order Count | E11: Profit Margin %
A12: Clothing | B12: =SUMIF('Cleaned Data'!$H:$H,A12,'Cleaned Data'!$N:$N) -> 165724.31 | C12: =SUMIF('Cleaned Data'!$H:$H,A12,'Cleaned Data'!$O:$O) -> 18533.6 | D12: =COUNTIF('Cleaned Data'!$H:$H,A12) -> 128 | E12: =IFERROR(C12/B12,"") -> 0.11183392
A13: Electronics | B13: =SUMIF('Cleaned Data'!$H:$H,A13,'Cleaned Data'!$N:$N) -> 192296.21 | C13: =SUMIF('Cleaned Data'!$H:$H,A13,'Cleaned Data'!$O:$O) -> 24954.71 | D13: =COUNTIF('Cleaned Data'!$H:$H,A13) -> 138 | E13: =IFERROR(C13/B13,"") -> 0.12977224
A14: Furniture | B14: =SUMIF('Cleaned Data'!$H:$H,A14,'Cleaned Data'!$N:$N) -> 180630.87 | C14: =SUMIF('Cleaned Data'!$H:$H,A14,'Cleaned Data'!$O:$O) -> 16382.72 | D14: =COUNTIF('Cleaned Data'!$H:$H,A14) -> 130 | E14: =IFERROR(C14/B14,"") -> 0.090697232
A15: Home & Kitchen | B15: =SUMIF('Cleaned Data'!$H:$H,A15,'Cleaned Data'!$N:$N) -> 190545.62 | C15: =SUMIF('Cleaned Data'!$H:$H,A15,'Cleaned Data'!$O:$O) -> 20397.9 | D15: =COUNTIF('Cleaned Data'!$H:$H,A15) -> 137 | E15: =IFERROR(C15/B15,"") -> 0.10704995
A16: Office Supplies | B16: =SUMIF('Cleaned Data'!$H:$H,A16,'Cleaned Data'!$N:$N) -> 154706.35 | C16: =SUMIF('Cleaned Data'!$H:$H,A16,'Cleaned Data'!$O:$O) -> 22089.54 | D16: =COUNTIF('Cleaned Data'!$H:$H,A16) -> 117 | E16: =IFERROR(C16/B16,"") -> 0.14278367
A18: Monthly Sales Trend
A19: Month | B19: Total Sales | C19: Total Profit
A20: Jan-2023 | B20: =SUMPRODUCT((TEXT('Cleaned Data'!$B$2:$B$651,"mmm-yyyy")=A20)*'Cleaned Data'!$N$2:$N$651) -> 40355.1 | C20: =SUMPRODUCT((TEXT('Cleaned Data'!$B$2:$B$651,"mmm-yyyy")=A20)*'Cleaned Data'!$O$2:$O$651) -> 4499.23
A21: Feb-2023 | B21: =SUMPRODUCT((TEXT('Cleaned Data'!$B$2:$B$651,"mmm-yyyy")=A21)*'Cleaned Data'!$N$2:$N$651) -> 40829.65 | C21: =SUMPRODUCT((TEXT('Cleaned Data'!$B$2:$B$651,"mmm-yyyy")=A21)*'Cleaned Data'!$O$2:$O$651) -> 3631.68
A22: Mar-2023 | B22: =SUMPRODUCT((TEXT('Cleaned Data'!$B$2:$B$651,"mmm-yyyy")=A22)*'Cleaned Data'!$N$2:$N$651) -> 44022.33 | C22: =SUMPRODUCT((TEXT('Cleaned Data'!$B$2:$B$651,"mmm-yyyy")=A22)*'Cleaned Data'!$O$2:$O$651) -> 4611.45
A23: Apr-2023 | B23: =SUMPRODUCT((TEXT('Cleaned Data'!$B$2:$B$651,"mmm-yyyy")=A23)*'Cleaned Data'!$N$2:$N$651) -> 23562.4 | C23: =SUMPRODUCT((TEXT('Cleaned Data'!$B$2:$B$651,"mmm-yyyy")=A23)*'Cleaned Data'!$O$2:$O$651) -> 2145.29
A24: May-2023 | B24: =SUMPRODUCT((TEXT('Cleaned Data'!$B$2:$B$651,"mmm-yyyy")=A24)*'Cleaned Data'!$N$2:$N$651) -> 37443.41 | C24: =SUMPRODUCT((TEXT('Cleaned Data'!$B$2:$B$651,"mmm-yyyy")=A24)*'Cleaned Data'!$O$2:$O$651) -> 6442.65
A25: Jun-2023 | B25: =SUMPRODUCT((TEXT('Cleaned Data'!$B$2:$B$651,"mmm-yyyy")=A25)*'Cleaned Data'!$N$2:$N$651) -> 16926.2 | C25: =SUMPRODUCT((TEXT('Cleaned Data'!$B$2:$B$651,"mmm-yyyy")=A25)*'Cleaned Data'!$O$2:$O$651) -> 2271.49
A26: Jul-2023 | B26: =SUMPRODUCT((TEXT('Cleaned Data'!$B$2:$B$651,"mmm-yyyy")=A26)*'Cleaned Data'!$N$2:$N$651) -> 36547.34 | C26: =SUMPRODUCT((TEXT('Cleaned Data'!$B$2:$B$651,"mmm-yyyy")=A26)*'Cleaned Data'!$O$2:$O$651) -> 5187.3
A27: Aug-2023 | B27: =SUMPRODUCT((TEXT('Cleaned Data'!$B$2:$B$651,"mmm-yyyy")=A27)*'Cleaned Data'!$N$2:$N$651) -> 25081.07 | C27: =SUMPRODUCT((TEXT('Cleaned Data'!$B$2:$B$651,"mmm-yyyy")=A27)*'Cleaned Data'!$O$2:$O$651) -> 4617.07
A28: Sep-2023 | B28: =SUMPRODUCT((TEXT('Cleaned Data'!$B$2:$B$651,"mmm-yyyy")=A28)*'Cleaned Data'!$N$2:$N$651) -> 20160.77 | C28: =SUMPRODUCT((TEXT('Cleaned Data'!$B$2:$B$651,"mmm-yyyy")=A28)*'Cleaned Data'!$O$2:$O$651) -> 1348.32
A29: Oct-2023 | B29: =SUMPRODUCT((TEXT('Cleaned Data'!$B$2:$B$651,"mmm-yyyy")=A29)*'Cleaned Data'!$N$2:$N$651) -> 47901.16 | C29: =SUMPRODUCT((TEXT('Cleaned Data'!$B$2:$B$651,"mmm-yyyy")=A29)*'Cleaned Data'!$O$2:$O$651) -> 5608.51
A30: Nov-2023 | B30: =SUMPRODUCT((TEXT('Cleaned Data'!$B$2:$B$651,"mmm-yyyy")=A30)*'Cleaned Data'!$N$2:$N$651) -> 40426.29 | C30: =SUMPRODUCT((TEXT('Cleaned Data'!$B$2:$B$651,"mmm-yyyy")=A30)*'Cleaned Data'!$O$2:$O$651) -> 4154.44
A31: Dec-2023 | B31: =SUMPRODUCT((TEXT('Cleaned Data'!$B$2:$B$651,"mmm-yyyy")=A31)*'Cleaned Data'!$N$2:$N$651) -> 29631.8 | C31: =SUMPRODUCT((TEXT('Cleaned Data'!$B$2:$B$651,"mmm-yyyy")=A31)*'Cleaned Data'!$O$2:$O$651) -> 4049.22
... A43: Dec-2024 | B43: =SUMPRODUCT((TEXT('Cleaned Data'!$B$2:$B$651,"mmm-yyyy")=A43)*'Cleaned Data'!$N$2:$N$651) -> 47673.25 | C43: =SUMPRODUCT((TEXT('Cleaned Data'!$B$2:$B$651,"mmm-yyyy")=A43)*'Cleaned Data'!$O$2:$O$651) -> 5879.85
A45: Segment Share of Sales
A46: Segment | B46: Total Sales | C46: % of Total Sales
A47: Consumer | B47: =SUMIF('Cleaned Data'!$E:$E,A47,'Cleaned Data'!$N:$N) -> 229370.52 | C47: =IFERROR(B47/$B$51,"") -> 0.25949728
A48: Corporate | B48: =SUMIF('Cleaned Data'!$E:$E,A48,'Cleaned Data'!$N:$N) -> 226808.75 | C48: =IFERROR(B48/$B$51,"") -> 0.25659904
A49: Home Office | B49: =SUMIF('Cleaned Data'!$E:$E,A49,'Cleaned Data'!$N:$N) -> 213297.21 | C49: =IFERROR(B49/$B$51,"") -> 0.24131282
A50: Unknown | B50: =SUMIF('Cleaned Data'!$E:$E,A50,'Cleaned Data'!$N:$N) -> 214426.88 | C50: =IFERROR(B50/$B$51,"") -> 0.24259086
A51: Total | B51: =SUM(B47:B50) -> 883903.36
A53: Top 10 Customers by Sales
A54: Customer Name | B54: Total Sales
A55: Noah Johnson | B55: =SUMIF('Cleaned Data'!$D:$D,A55,'Cleaned Data'!$N:$N) -> 9408.73
A56: Hassan Petrov | B56: =SUMIF('Cleaned Data'!$D:$D,A56,'Cleaned Data'!$N:$N) -> 9335.2
...
